Workbook

Sheet Sketch Guide
A1: Standard Combinations for Mix Utility/Car/Equip/Tilt Loads
C4: Overall length Cannot Exceed 53' | F4: =MAX(I10:I15)+MAX(L10:L14) -> 0
C5: Max Length of Stack #1 & Stack #2 cannot exceed 40' | J5: Max Length on Stack #3 Cannot Exceed 15.5'
C6: =MAX(I11:I15) -> 0 | J6: =MAX(L10:L14) -> 0
C7: Stack #1 Height Cannot Exceed 5.25 | F7: Stack #2 Height Cannot Exceed 5.25 | J7: Stack #3 Height Cannot Exceed 4
C8: =SUM(D10:D15) -> 0 | F8: =SUM(G10:G15) -> 0 | J8: =SUM(K10:K14) -> 0
C9: Stack #1 - Rear of Semi | F9: Stack #2 - Middle of Semi | J9: Stack #3 - Front of Semi
D10: =_xlfn.XLOOKUP(C10,Data!$D:$D,Data!$J:$J) -> 0 | E10: =_xlfn.XLOOKUP(C10,Data!$D:$D,Data!$G:$G)+_xlfn.XLOOKUP(C10,Data!$D:$D,Data!$I:$I) -> 0 | G10: =_xlfn.XLOOKUP(F10,Data!$D:$D,Data!$J:$J) -> 0 | H10: {=_xlfn.XLOOKUP(F10,Data!$D:$D,Data!$G:$G)+_xlfn.XLOOKUP(F10,Data!$D:$D,Data!$I:$I/2)} -> 0 | I10: =SUM(E10+H10) -> 0 | K10: =_xlfn.XLOOKUP(J10,Data!$D:$D,Data!$J:$J) -> 0 | L10: {=_xlfn.XLOOKUP(J10,Data!$D:$D,Data!$G:$G)+_xlfn.XLOOKUP(J10,Data!$D:$D,Data!$I:$I/2)} -> 0
D11: =_xlfn.XLOOKUP(C11,Data!$D:$D,Data!$J:$J) -> 0 | E11: =_xlfn.XLOOKUP(C11,Data!$D:$D,Data!$G:$G)+_xlfn.XLOOKUP(C11,Data!$D:$D,Data!$I:$I) -> 0 | G11: =_xlfn.XLOOKUP(F11,Data!$D:$D,Data!$J:$J) -> 0 | H11: {=_xlfn.XLOOKUP(F11,Data!$D:$D,Data!$G:$G)+_xlfn.XLOOKUP(F11,Data!$D:$D,Data!$I:$I/2)} -> 0 | I11: =SUM(E11+H11) -> 0 | K11: =_xlfn.XLOOKUP(J11,Data!$D:$D,Data!$J:$J) -> 0 | L11: {=_xlfn.XLOOKUP(J11,Data!$D:$D,Data!$G:$G)+_xlfn.XLOOKUP(J11,Data!$D:$D,Data!$I:$I/2)} -> 0
A12: 3 Stack Combination | D12: =_xlfn.XLOOKUP(C12,Data!$D:$D,Data!$J:$J) -> 0 | E12: =_xlfn.XLOOKUP(C12,Data!$D:$D,Data!$G:$G)+_xlfn.XLOOKUP(C12,Data!$D:$D,Data!$I:$I) -> 0 | G12: =_xlfn.XLOOKUP(F12,Data!$D:$D,Data!$J:$J) -> 0 | H12: {=_xlfn.XLOOKUP(F12,Data!$D:$D,Data!$G:$G)+_xlfn.XLOOKUP(F12,Data!$D:$D,Data!$I:$I/2)} -> 0 | I12: =SUM(E12+H12) -> 0 | K12: =_xlfn.XLOOKUP(J12,Data!$D:$D,Data!$J:$J) -> 0 | L12: {=_xlfn.XLOOKUP(J12,Data!$D:$D,Data!$G:$G)+_xlfn.XLOOKUP(J12,Data!$D:$D,Data!$I:$I/2)} -> 0
A13: for Utilities | D13: =_xlfn.XLOOKUP(C13,Data!$D:$D,Data!$J:$J) -> 0 | E13: =_xlfn.XLOOKUP(C13,Data!$D:$D,Data!$G:$G)+_xlfn.XLOOKUP(C13,Data!$D:$D,Data!$I:$I) -> 0 | G13: =_xlfn.XLOOKUP(F13,Data!$D:$D,Data!$J:$J) -> 0 | H13: {=_xlfn.XLOOKUP(F13,Data!$D:$D,Data!$G:$G)+_xlfn.XLOOKUP(F13,Data!$D:$D,Data!$I:$I/2)} -> 0 | I13: =SUM(E13+H13) -> 0 | K13: =_xlfn.XLOOKUP(J13,Data!$D:$D,Data!$J:$J) -> 0 | L13: {=_xlfn.XLOOKUP(J13,Data!$D:$D,Data!$G:$G)+_xlfn.XLOOKUP(J13,Data!$D:$D,Data!$I:$I/2)} -> 0
D14: =_xlfn.XLOOKUP(C14,Data!$D:$D,Data!$J:$J) -> 0 | E14: =_xlfn.XLOOKUP(C14,Data!$D:$D,Data!$G:$G)+_xlfn.XLOOKUP(C14,Data!$D:$D,Data!$I:$I) -> 0 | G14: =_xlfn.XLOOKUP(F14,Data!$D:$D,Data!$J:$J) -> 0 | H14: {=_xlfn.XLOOKUP(F14,Data!$D:$D,Data!$G:$G)+_xlfn.XLOOKUP(F14,Data!$D:$D,Data!$I:$I/2)} -> 0 | I14: =SUM(E14+H14) -> 0 | K14: =_xlfn.XLOOKUP(J14,Data!$D:$D,Data!$J:$J) -> 0 | L14: {=_xlfn.XLOOKUP(J14,Data!$D:$D,Data!$G:$G)+_xlfn.XLOOKUP(J14,Data!$D:$D,Data!$I:$I/2)} -> 0
D15: =_xlfn.XLOOKUP(C15,Data!$D:$D,Data!$J:$J) -> 0 | E15: =_xlfn.XLOOKUP(C15,Data!$D:$D,Data!$G:$G)+_xlfn.XLOOKUP(C15,Data!$D:$D,Data!$I:$I) -> 0 | G15: =_xlfn.XLOOKUP(F15,Data!$D:$D,Data!$J:$J) -> 0 | H15: {=_xlfn.XLOOKUP(F15,Data!$D:$D,Data!$G:$G)+_xlfn.XLOOKUP(F15,Data!$D:$D,Data!$I:$I/2)} -> 0 | I15: =SUM(E15+H15) -> 0
C20: Overall length Cannot Exceed 53' | F20: =MAX(I26:I30) -> 0
C21: Max Length of Stack #1 & Stack #2 cannot exceed 40.5'
C22: =I31 -> 0
C23: Stack #1 Height Cannot Exceed 5.25 | F23: Stack #3 Height Cannot Exceed 4
C24: =SUM(D26:D31) -> 0 | F24: =SUM(K26:K30) -> 0
C25: Stack #1 - Rear of Semi | F25: Stack #2 - Middle of Semi | J25: Stack #3 - Front of Semi
D26: =_xlfn.XLOOKUP(C26,Data!$D:$D,Data!$J:$J) -> 0 | E26: =_xlfn.XLOOKUP(C26,Data!$D:$D,Data!$G:$G)+_xlfn.XLOOKUP(C26,Data!$D:$D,Data!$I:$I) -> 0 | I26: =SUM(E26+L26) -> 0 | K26: =_xlfn.XLOOKUP(J26,Data!$D:$D,Data!$J:$J) -> 0 | L26: =_xlfn.XLOOKUP(J26,Data!$D:$D,Data!$G:$G)+_xlfn.XLOOKUP(J26,Data!$D:$D,Data!$I:$I) -> 0
D27: =_xlfn.XLOOKUP(C27,Data!$D:$D,Data!$J:$J) -> 0 | E27: =_xlfn.XLOOKUP(C27,Data!$D:$D,Data!$G:$G)+_xlfn.XLOOKUP(C27,Data!$D:$D,Data!$I:$I) -> 0 | I27: =SUM(E27+L27) -> 0 | K27: =_xlfn.XLOOKUP(J27,Data!$D:$D,Data!$J:$J) -> 0 | L27: =_xlfn.XLOOKUP(J27,Data!$D:$D,Data!$G:$G)+_xlfn.XLOOKUP(J27,Data!$D:$D,Data!$I:$I) -> 0
A28: 2 Stack Combination | D28: =_xlfn.XLOOKUP(C28,Data!$D:$D,Data!$J:$J) -> 0 | E28: =_xlfn.XLOOKUP(C28,Data!$D:$D,Data!$G:$G)+_xlfn.XLOOKUP(C28,Data!$D:$D,Data!$I:$I) -> 0 | I28: =SUM(E28+L28) -> 0 | K28: =_xlfn.XLOOKUP(J28,Data!$D:$D,Data!$J:$J) -> 0 | L28: =_xlfn.XLOOKUP(J28,Data!$D:$D,Data!$G:$G)+_xlfn.XLOOKUP(J28,Data!$D:$D,Data!$I:$I) -> 0
A29: for Utilities | D29: =_xlfn.XLOOKUP(C29,Data!$D:$D,Data!$J:$J) -> 0 | E29: =_xlfn.XLOOKUP(C29,Data!$D:$D,Data!$G:$G)+_xlfn.XLOOKUP(C29,Data!$D:$D,Data!$I:$I) -> 0 | F29: Stack #2 will be a single unit if the | I29: =SUM(E29+L29) -> 0 | K29: =_xlfn.XLOOKUP(J29,Data!$D:$D,Data!$J:$J) -> 0 | L29: =_xlfn.XLOOKUP(J29,Data!$D:$D,Data!$G:$G)+_xlfn.XLOOKUP(J29,Data!$D:$D,Data!$I:$I) -> 0
D30: =_xlfn.XLOOKUP(C30,Data!$D:$D,Data!$J:$J) -> 0 | E30: =_xlfn.XLOOKUP(C30,Data!$D:$D,Data!$G:$G)+_xlfn.XLOOKUP(C30,Data!$D:$D,Data!$I:$I) -> 0 | F30: length works and cannot be a SV or TV | I30: =SUM(E30+L30) -> 0 | K30: =_xlfn.XLOOKUP(J30,Data!$D:$D,Data!$J:$J) -> 0 | L30: =_xlfn.XLOOKUP(J30,Data!$D:$D,Data!$G:$G)+_xlfn.XLOOKUP(J30,Data!$D:$D,Data!$I:$I) -> 0
D31: =_xlfn.XLOOKUP(C31,Data!$D:$D,Data!$J:$J) -> 0 | E31: =_xlfn.XLOOKUP(C31,Data!$D:$D,Data!$G:$G)+_xlfn.XLOOKUP(C31,Data!$D:$D,Data!$I:$I) -> 0 | H31: {=_xlfn.XLOOKUP(F31,Data!$D:$D,Data!$G:$G)+_xlfn.XLOOKUP(F31,Data!$D:$D,Data!$I:$I/2)} -> 0 | I31: =SUM(E31+H31) -> 0
C36: Overall length Cannot Exceed 53' | F36: =MAX(I42:I47)+MAX(L42:L46) -> 0
C37: Stack #1 Length Cannot Exceed 21' | F37: Stack #2 Length Cannot Exceed 16' | J37: Max Length on Stack #3 Cannot Exceed 16'
C38: =MAX(E42:E47) -> 0 | F38: =MAX(H42:H47) -> 0 | J38: =MAX(L42:L46) -> 0
C39: Stack #1 Height Cannot Exceed 5 | F39: Stack #2 Height Cannot Exceed 5 | J39: Stack #3 Height Cannot Exceed 5
C40: =SUM(D42:D47) -> 0 | F40: =SUM(G42:G47) -> 0 | J40: =SUM(K42:K46) -> 0
C41: Stack #1 - Rear of Semi | F41: Stack #2 - Middle of Semi | J41: Stack #3 - Front of Semi
D42: =_xlfn.XLOOKUP(C42,Data!$D:$D,Data!$J:$J) -> 0 | E42: =_xlfn.XLOOKUP(C42,Data!$D:$D,Data!$G:$G)+_xlfn.XLOOKUP(C42,Data!$D:$D,Data!$I:$I) -> 0 | G42: =_xlfn.XLOOKUP(F42,Data!$D:$D,Data!$J:$J) -> 0 | H42: {=_xlfn.XLOOKUP(F42,Data!$D:$D,Data!$G:$G)+_xlfn.XLOOKUP(F42,Data!$D:$D,Data!$I:$I/2.5)} -> 0 | I42: =SUM(E42+H42) -> 0 | K42: =_xlfn.XLOOKUP(J42,Data!$D:$D,Data!$J:$J) -> 0 | L42: {=_xlfn.XLOOKUP(J42,Data!$D:$D,Data!$G:$G)+_xlfn.XLOOKUP(J42,Data!$D:$D,Data!$I:$I/2.5)} -> 0
D43: =_xlfn.XLOOKUP(C43,Data!$D:$D,Data!$J:$J) -> 0 | E43: =_xlfn.XLOOKUP(C43,Data!$D:$D,Data!$G:$G)+_xlfn.XLOOKUP(C43,Data!$D:$D,Data!$I:$I) -> 0 | G43: =_xlfn.XLOOKUP(F43,Data!$D:$D,Data!$J:$J) -> 0 | H43: {=_xlfn.XLOOKUP(F43,Data!$D:$D,Data!$G:$G)+_xlfn.XLOOKUP(F43,Data!$D:$D,Data!$I:$I/2.5)} -> 0 | I43: =SUM(E43+H43) -> 0 | K43: =_xlfn.XLOOKUP(J43,Data!$D:$D,Data!$J:$J) -> 0 | L43: {=_xlfn.XLOOKUP(J43,Data!$D:$D,Data!$G:$G)+_xlfn.XLOOKUP(J43,Data!$D:$D,Data!$I:$I/2.5)} -> 0
A44: Dump Load | D44: =_xlfn.XLOOKUP(C44,Data!$D:$D,Data!$J:$J) -> 0 | E44: =_xlfn.XLOOKUP(C44,Data!$D:$D,Data!$G:$G)+_xlfn.XLOOKUP(C44,Data!$D:$D,Data!$I:$I) -> 0 | G44: =_xlfn.XLOOKUP(F44,Data!$D:$D,Data!$J:$J) -> 0 | H44: {=_xlfn.XLOOKUP(F44,Data!$D:$D,Data!$G:$G)+_xlfn.XLOOKUP(F44,Data!$D:$D,Data!$I:$I/2.5)} -> 0 | I44: =SUM(E44+H44) -> 0 | K44: =_xlfn.XLOOKUP(J44,Data!$D:$D,Data!$J:$J) -> 0 | L44: {=_xlfn.XLOOKUP(J44,Data!$D:$D,Data!$G:$G)+_xlfn.XLOOKUP(J44,Data!$D:$D,Data!$I:$I/2.5)} -> 0
A45: Combination | D45: =_xlfn.XLOOKUP(C45,Data!$D:$D,Data!$J:$J) -> 0 | E45: =_xlfn.XLOOKUP(C45,Data!$D:$D,Data!$G:$G)+_xlfn.XLOOKUP(C45,Data!$D:$D,Data!$I:$I) -> 0 | G45: =_xlfn.XLOOKUP(F45,Data!$D:$D,Data!$J:$J) -> 0 | H45: {=_xlfn.XLOOKUP(F45,Data!$D:$D,Data!$G:$G)+_xlfn.XLOOKUP(F45,Data!$D:$D,Data!$I:$I/2.5)} -> 0 | I45: =SUM(E45+H45) -> 0 | K45: =_xlfn.XLOOKUP(J45,Data!$D:$D,Data!$J:$J) -> 0 | L45: {=_xlfn.XLOOKUP(J45,Data!$D:$D,Data!$G:$G)+_xlfn.XLOOKUP(J45,Data!$D:$D,Data!$I:$I/2.5)} -> 0
D46: =_xlfn.XLOOKUP(C46,Data!$D:$D,Data!$J:$J) -> 0 | E46: =_xlfn.XLOOKUP(C46,Data!$D:$D,Data!$G:$G)+_xlfn.XLOOKUP(C46,Data!$D:$D,Data!$I:$I) -> 0 | G46: =_xlfn.XLOOKUP(F46,Data!$D:$D,Data!$J:$J) -> 0 | H46: {=_xlfn.XLOOKUP(F46,Data!$D:$D,Data!$G:$G)+_xlfn.XLOOKUP(F46,Data!$D:$D,Data!$I:$I/2.5)} -> 0 | I46: =SUM(E46+H46) -> 0 | K46: =_xlfn.XLOOKUP(J46,Data!$D:$D,Data!$J:$J) -> 0 | L46: {=_xlfn.XLOOKUP(J46,Data!$D:$D,Data!$G:$G)+_xlfn.XLOOKUP(J46,Data!$D:$D,Data!$I:$I/2.5)} -> 0
D47: =_xlfn.XLOOKUP(C47,Data!$D:$D,Data!$J:$J) -> 0 | E47: =_xlfn.XLOOKUP(C47,Data!$D:$D,Data!$G:$G)+_xlfn.XLOOKUP(C47,Data!$D:$D,Data!$I:$I) -> 0 | G47: =_xlfn.XLOOKUP(F47,Data!$D:$D,Data!$J:$J) -> 0 | H47: {=_xlfn.XLOOKUP(F47,Data!$D:$D,Data!$G:$G)+_xlfn.XLOOKUP(F47,Data!$D:$D,Data!$I:$I/2.5)} -> 0 | I47: =SUM(E47+H47) -> 0
C52: Overall length Cannot Exceed 53' | F52: =MAX(I61:I65) -> 0
C53: To Get (4) Goosenecks on a load, Fourth Trailer must be 44' overall or shorter
C54: =L62 -> 0
...

Sheet Dumps
A1: Standard Combinations for Dump Loads
A3: Dump Models | B3: Width | D3: Notes: | E3: 1 | F3: A 6' x 10' or 6' x 12' wide trailer can be substituted in place of a 7' wide trailer. If only replacing one unit, the 6' wide must be on the top of the stack.
A4: 70SR | B4: 5' | E4: 2 | F4: If you have a load with all 10' long dumps, you can get four stacks of two
A5: 90SR | B5: 6' | E5: 3 | F5: You can stuff a 5' x 8' or 5'x 10' utility, Vanguard or dump inside the top dump in Stack #1 & Stack #2
A6: 10LX | B6: 7' | E6: 4 | F6: 25DU is 92" inside width so you can only stuff a 5' wide trailer inside
A7: 14LX | B7: 7'
A8: 14LP | B8: 7'
A9: 14TD | B9: 7' | D9: Exceptions: | E9: 1 | F9: A 20LP-16 dump has 3' sides standard, so you can only get a 2' sided dump on top of it.
A10: 14XD | B10: 7' | E10: 2 | F10: If Stack #1 and Stack #2 have a TD model that is 16' then the step deck needs to be 12' or smaller
A11: 14GX | B11: 7' | E11: 3 | F11: If a GN Dump is added to the load, you cannot stuff a unit in stack #1
A12: 14GT | B12: 7' | E12: 4 | F12: If a dump has hydraulic jacks(s), it cannot go in the Stack #2. It has to go in either Stack #1 or Stack #3
A13: 16LP | B13: 7'
A14: 16TD | B14: 7'
A15: 16GX | B15: 7'
A16: 20LP | B16: 7' | F16: Stack #1 - Rear of Semi | H16: Stack #2 - Middle of Semi | J16: Stack #3 - Front of Semi
A17: 20GX | B17: 7' | D17: All Bumper | F17: 7' x 12', 14' or 16' -2' or 4' sides | H17: 7' x 12', 14' or 16' -2' or 4' sides | J17: 7' x 12' or 14' -2' sides
A18: 25DU | B18: 92" | F18: 7' x 12', 14' or 16' -2' sides | H18: 7' x 12', 14' or 16' -2' sides | J18: 7' x 12' or 14' -2' sides | K18: or | L18: 7' x 12', or 14' -4' sides
D20: GN Dump | F20: 7' x 12', 14' or 16' -2' or 4' sides | H20: 7' x 14' or 16' GN dump - 2' or 4' sides | J20: 7' x 12' or 14' -2' sides
D21: Included | F21: 7' x 12', 14' or 16' -2' sides | H21: 7' x 12', 14' or 16' -2' sides | J21: 7' x 12' or 14' -2' sides | K21: or | L21: 7' x 12', or 14' -4' sides
D23: 2 GN Dumps | F23: 7' x 14' or 16' GN dump - 2' or 4' sides | J23: 7' x 12' or 14' -2' sides
D24: Included | F24: 7' x 14' or 16' GN dump - 2' sides | H24: 5' x 10', 6' x 10', 6' x 12', 7' x 12' - 2' sides | J24: 7' x 12' or 14' -2' sides | K24: or | L24: 7' x 12', or 14' -4' sides
D26: All GN Dumps | F26: 7' x 14' or 16' GN dump - 2' or 4' sides | H26: 7' x 14' or 16' GN dump - 2' or 4' sides
F27: 7' x 14' or 16' GN dump - 2' sides | H27: 7' x 14' or 16' GN dump - 2' sides
D29: (1) 25DU load | F29: Stack #1 can consist of (5) units up to | H29: 22' max length, no Vanguard
F30: 20' if no units have sides. You can
F31: get (4) units if they have sides.
F32: No OA/OT models can go in this | H32: 25DU-20
F33: stack.
D35: (2) 25DU Load | F35: 20' max length, no Vanguard | H35: 20' max length, no Vanguard
F37: 25DU-20 | H37: 25DU-20

Sheet Goosenecks
A1: Standard Combinations for Gooseneck Loads
A3: GN Models | B3: Wheels | D3: Notes: | E3: 1 | F3: If all units are tandem dual, the bottom trailer must be a 20+5 or shorter and second trailer must be a 33' or longer
A4: 14GN | B4: Single | E4: 2 | F4: If you have all single wheels, then you can have a (4) stack of 20+5 and 25+5 units
A5: 16GN | B5: Single | E5: 3 | F5: If you have a mix of tandem dual and single, the shortest goes on the bottom then the longest to shortest
A6: 14PH | B6: Single | E6: 4 | F6: If you have all PH models, stack them longest to shortest
A7: 22GN | B7: Dual | E7: 5 | F7: If all units single wheel, tandem dual or comnbination of both are 20+5, then you can still get (4) on a load
A8: 25GN | B8: Dual | E8: 6 | F8: (3) 40' goosenecks is a full semi load
A9: 22PH | B9: Dual | E9: 7 | F9: An OA model can replace any gooseneck or pintle(20+5 or 25+5), but cannot be the bottom trailer on a the load.
A10: 25PH | B10: Dual
D11: Exceptions: | E11: 1 | F11: If you do not have a unit that is, or less than 25' overall, then you can only get three goosenecks on a semi load.
E12: 2 | F12: If you do a one ton load, you cannot have more than (2) the same length, you have to stack longest to shortest and you cannot exceed the GVWR of the bottom trailer
F16: Semi Stacks
D17: All Tandem | F17: GN - 33' or shorter or PH - 30' or shorter
D18: Duals | F18: GN - 40' or shorter
F19: GN - 33' to 40'
F20: GN - 20+5 or shorter - PH - 20+5 or shorter
D22: All Single | F22: GN - 33' or shorter or PH - 30' or shorter
D23: Wheels | F23: GN - 40' or shorter
F24: GN - 40' or shorter
F25: GN - 30' or shorter or PH - 30' or shorter
D27: Mix of Tandem | F27: GN - 33' or shorter or PH - 30' or shorter
D28: Dual & Single | F28: GN - 40' or shorter
D29: Wheel | F29: GN - 40' or shorter
F30: GN - 25+5 or shorter - PH - 20+5 or shorter

Sheet Data
A1: Mcat | B1: Tier | C1: Model | D1: ItemNumber | E1: GVWR | F1: Floor Type | G1: Bed Length | H1: Width | I1: Tongue | J1: Stack Height
A2: CAR HAULER | B2: 4 | C2: 10CH | D2: 10CH-16 | E2: 9990 | F2: Wood | G2: 16 | H2: 7 | I2: 4 | J2: 0.75
A3: CAR HAULER | B3: 4 | C3: 10CH | D3: 10CH-16BKDT | E3: 9990 | F3: Wood | G3: 16 | H3: 7 | I3: 4 | J3: 0.75
A4: CAR HAULER | B4: 3 | C4: 10CH | D4: 10CH-18 | E4: 9990 | F4: Wood | G4: 18 | H4: 7 | I4: 4 | J4: 0.75
A5: CAR HAULER | B5: 3 | C5: 10CH | D5: 10CH-18BK | E5: 9990 | F5: Wood | G5: 18 | H5: 7 | I5: 4 | J5: 0.75
A6: CAR HAULER | B6: 2 | C6: 10CH | D6: 10CH-18BKDT | E6: 9990 | F6: Wood | G6: 18 | H6: 7 | I6: 4 | J6: 0.75
A7: CAR HAULER | B7: 3 | C7: 10CH | D7: 10CH-20 | E7: 9990 | F7: Wood | G7: 20 | H7: 7 | I7: 4 | J7: 0.75
A8: CAR HAULER | B8: 3 | C8: 10CH | D8: 10CH-20BK | E8: 9990 | F8: Wood | G8: 20 | H8: 7 | I8: 4 | J8: 0.75
A9: CAR HAULER | B9: 2 | C9: 10CH | D9: 10CH-20BKDT | E9: 9990 | F9: Wood | G9: 20 | H9: 7 | I9: 4 | J9: 0.75
A10: CAR HAULER | B10: 4 | C10: 10CH | D10: 10CH-20BKDT5FUR | E10: 9990 | F10: Wood | G10: 20 | H10: 7 | I10: 4 | J10: 0.75
A11: CAR HAULER | B11: 3 | C11: 10DM | D11: 10DM-18 | E11: 9990 | F11: Steel | G11: 18 | H11: 7 | I11: 5 | J11: 0.75
A12: CAR HAULER | B12: 3 | C12: 10DM | D12: 10DM-18BK | E12: 9990 | F12: Steel | G12: 18 | H12: 7 | I12: 5 | J12: 0.75
A13: CAR HAULER | B13: 3 | C13: 10DM | D13: 10DM-20 | E13: 9990 | F13: Steel | G13: 20 | H13: 7 | I13: 5 | J13: 0.75
... A717: VANGUARD/LANDSCAPE | B717: 3 | C717: 70TV | D717: 70TV-18BK2B | E717: 7000 | F717: Wood | G717: 18 | H717: 7 | I717: 3 | J717: 2
